{
 "cells": [
  {
   "cell_type": "code",
   "execution_count": 9,
   "metadata": {},
   "outputs": [
    {
     "name": "stdout",
     "output_type": "stream",
     "text": [
      "Collecting ta-lib\n",
      "  Downloading TA-Lib-0.4.28.tar.gz (357 kB)\n",
      "\u001b[2K     \u001b[90m━━━━━━━━━━━━━━━━━━━━━━━━━━━━━━━━━━━━━━━\u001b[0m \u001b[32m357.1/357.1 kB\u001b[0m \u001b[31m1.4 MB/s\u001b[0m eta \u001b[36m0:00:00\u001b[0ma \u001b[36m0:00:01\u001b[0m\n",
      "\u001b[?25h  Installing build dependencies ... \u001b[?25ldone\n",
      "\u001b[?25h  Getting requirements to build wheel ... \u001b[?25ldone\n",
      "\u001b[?25h  Installing backend dependencies ... \u001b[?25ldone\n",
      "\u001b[?25h  Preparing metadata (pyproject.toml) ... \u001b[?25ldone\n",
      "\u001b[?25hRequirement already satisfied: numpy in /home/saosman/anaconda3/lib/python3.7/site-packages (from ta-lib) (1.21.6)\n",
      "Building wheels for collected packages: ta-lib\n",
      "  Building wheel for ta-lib (pyproject.toml) ... \u001b[?25lerror\n",
      "  \u001b[1;31merror\u001b[0m: \u001b[1msubprocess-exited-with-error\u001b[0m\n",
      "  \n",
      "  \u001b[31m×\u001b[0m \u001b[32mBuilding wheel for ta-lib \u001b[0m\u001b[1;32m(\u001b[0m\u001b[32mpyproject.toml\u001b[0m\u001b[1;32m)\u001b[0m did not run successfully.\n",
      "  \u001b[31m│\u001b[0m exit code: \u001b[1;36m1\u001b[0m\n",
      "  \u001b[31m╰─>\u001b[0m \u001b[31m[22 lines of output]\u001b[0m\n",
      "  \u001b[31m   \u001b[0m running bdist_wheel\n",
      "  \u001b[31m   \u001b[0m running build\n",
      "  \u001b[31m   \u001b[0m running build_py\n",
      "  \u001b[31m   \u001b[0m creating build\n",
      "  \u001b[31m   \u001b[0m creating build/lib.linux-x86_64-cpython-37\n",
      "  \u001b[31m   \u001b[0m creating build/lib.linux-x86_64-cpython-37/talib\n",
      "  \u001b[31m   \u001b[0m copying talib/__init__.py -> build/lib.linux-x86_64-cpython-37/talib\n",
      "  \u001b[31m   \u001b[0m copying talib/abstract.py -> build/lib.linux-x86_64-cpython-37/talib\n",
      "  \u001b[31m   \u001b[0m copying talib/deprecated.py -> build/lib.linux-x86_64-cpython-37/talib\n",
      "  \u001b[31m   \u001b[0m copying talib/stream.py -> build/lib.linux-x86_64-cpython-37/talib\n",
      "  \u001b[31m   \u001b[0m running build_ext\n",
      "  \u001b[31m   \u001b[0m building 'talib._ta_lib' extension\n",
      "  \u001b[31m   \u001b[0m creating build/temp.linux-x86_64-cpython-37\n",
      "  \u001b[31m   \u001b[0m creating build/temp.linux-x86_64-cpython-37/talib\n",
      "  \u001b[31m   \u001b[0m gcc -pthread -B /home/saosman/anaconda3/compiler_compat -Wl,--sysroot=/ -Wsign-compare -DNDEBUG -g -fwrapv -O3 -Wall -Wstrict-prototypes -fPIC -I/usr/include -I/usr/local/include -I/opt/include -I/opt/local/include -I/opt/homebrew/include -I/opt/homebrew/opt/ta-lib/include -I/tmp/pip-build-env-nxt_0ykr/normal/lib/python3.7/site-packages/numpy/core/include -I/home/saosman/anaconda3/include/python3.7m -c talib/_ta_lib.c -o build/temp.linux-x86_64-cpython-37/talib/_ta_lib.o\n",
      "  \u001b[31m   \u001b[0m talib/_ta_lib.c:1082:10: fatal error: ta-lib/ta_defs.h: No such file or directory\n",
      "  \u001b[31m   \u001b[0m  1082 | #include \"ta-lib/ta_defs.h\"\n",
      "  \u001b[31m   \u001b[0m       |          ^~~~~~~~~~~~~~~~~~\n",
      "  \u001b[31m   \u001b[0m compilation terminated.\n",
      "  \u001b[31m   \u001b[0m /tmp/pip-install-gsjnut1w/ta-lib_efa6004d79f8498fb7fe616555b0cc04/setup.py:77: UserWarning: Cannot find ta-lib library, installation may fail.\n",
      "  \u001b[31m   \u001b[0m   warnings.warn('Cannot find ta-lib library, installation may fail.')\n",
      "  \u001b[31m   \u001b[0m error: command '/usr/bin/gcc' failed with exit code 1\n",
      "  \u001b[31m   \u001b[0m \u001b[31m[end of output]\u001b[0m\n",
      "  \n",
      "  \u001b[1;35mnote\u001b[0m: This error originates from a subprocess, and is likely not a problem with pip.\n",
      "\u001b[31m  ERROR: Failed building wheel for ta-lib\u001b[0m\u001b[31m\n",
      "\u001b[0m\u001b[?25hFailed to build ta-lib\n",
      "\u001b[31mERROR: Could not build wheels for ta-lib, which is required to install pyproject.toml-based projects\u001b[0m\u001b[31m\n",
      "\u001b[0mRequirement already satisfied: pep517 in /home/saosman/anaconda3/lib/python3.7/site-packages (0.13.0)\n",
      "Requirement already satisfied: tomli>=1.1.0 in /home/saosman/anaconda3/lib/python3.7/site-packages (from pep517) (2.0.1)\n",
      "Requirement already satisfied: importlib_metadata in /home/saosman/anaconda3/lib/python3.7/site-packages (from pep517) (6.6.0)\n",
      "Requirement already satisfied: zipp in /home/saosman/anaconda3/lib/python3.7/site-packages (from pep517) (3.15.0)\n",
      "Requirement already satisfied: typing-extensions>=3.6.4 in /home/saosman/anaconda3/lib/python3.7/site-packages (from importlib_metadata->pep517) (4.6.1)\n",
      "\u001b[33mWARNING: Running pip as the 'root' user can result in broken permissions and conflicting behaviour with the system package manager. It is recommended to use a virtual environment instead: https://pip.pypa.io/warnings/venv\u001b[0m\u001b[33m\n",
      "\u001b[0mRequirement already satisfied: tensorflow in /home/saosman/anaconda3/lib/python3.7/site-packages (1.12.0)\n",
      "Collecting tensorflow-gpu\n",
      "  Using cached tensorflow-gpu-2.12.0.tar.gz (2.6 kB)\n",
      "  Preparing metadata (setup.py) ... \u001b[?25lerror\n",
      "  \u001b[1;31merror\u001b[0m: \u001b[1msubprocess-exited-with-error\u001b[0m\n",
      "  \n",
      "  \u001b[31m×\u001b[0m \u001b[32mpython setup.py egg_info\u001b[0m did not run successfully.\n",
      "  \u001b[31m│\u001b[0m exit code: \u001b[1;36m1\u001b[0m\n",
      "  \u001b[31m╰─>\u001b[0m \u001b[31m[39 lines of output]\u001b[0m\n",
      "  \u001b[31m   \u001b[0m Traceback (most recent call last):\n",
      "  \u001b[31m   \u001b[0m   File \"/home/saosman/anaconda3/lib/python3.7/site-packages/setuptools/_vendor/packaging/requirements.py\", line 35, in __init__\n",
      "  \u001b[31m   \u001b[0m     parsed = _parse_requirement(requirement_string)\n",
      "  \u001b[31m   \u001b[0m   File \"/home/saosman/anaconda3/lib/python3.7/site-packages/setuptools/_vendor/packaging/_parser.py\", line 64, in parse_requirement\n",
      "  \u001b[31m   \u001b[0m     return _parse_requirement(Tokenizer(source, rules=DEFAULT_RULES))\n",
      "  \u001b[31m   \u001b[0m   File \"/home/saosman/anaconda3/lib/python3.7/site-packages/setuptools/_vendor/packaging/_parser.py\", line 82, in _parse_requirement\n",
      "  \u001b[31m   \u001b[0m     url, specifier, marker = _parse_requirement_details(tokenizer)\n",
      "  \u001b[31m   \u001b[0m   File \"/home/saosman/anaconda3/lib/python3.7/site-packages/setuptools/_vendor/packaging/_parser.py\", line 132, in _parse_requirement_details\n",
      "  \u001b[31m   \u001b[0m     else \"name and no valid version specifier\"\n",
      "  \u001b[31m   \u001b[0m   File \"/home/saosman/anaconda3/lib/python3.7/site-packages/setuptools/_vendor/packaging/_parser.py\", line 149, in _parse_requirement_marker\n",
      "  \u001b[31m   \u001b[0m     span_start=span_start,\n",
      "  \u001b[31m   \u001b[0m   File \"/home/saosman/anaconda3/lib/python3.7/site-packages/setuptools/_vendor/packaging/_tokenizer.py\", line 168, in raise_syntax_error\n",
      "  \u001b[31m   \u001b[0m     span=span,\n",
      "  \u001b[31m   \u001b[0m setuptools.extern.packaging._tokenizer.ParserSyntaxError: Expected end or semicolon (after name and no valid version specifier)\n",
      "  \u001b[31m   \u001b[0m     python_version>\"3.7\"\n",
      "  \u001b[31m   \u001b[0m                   ^\n",
      "  \u001b[31m   \u001b[0m \n",
      "  \u001b[31m   \u001b[0m The above exception was the direct cause of the following exception:\n",
      "  \u001b[31m   \u001b[0m \n",
      "  \u001b[31m   \u001b[0m Traceback (most recent call last):\n",
      "  \u001b[31m   \u001b[0m   File \"<string>\", line 36, in <module>\n",
      "  \u001b[31m   \u001b[0m   File \"<pip-setuptools-caller>\", line 34, in <module>\n",
      "  \u001b[31m   \u001b[0m   File \"/tmp/pip-install-s_pjduqi/tensorflow-gpu_7e620855d5a24a1394ab7977d91795dc/setup.py\", line 40, in <module>\n",
      "  \u001b[31m   \u001b[0m     setuptools.setup()\n",
      "  \u001b[31m   \u001b[0m   File \"/home/saosman/anaconda3/lib/python3.7/site-packages/setuptools/__init__.py\", line 106, in setup\n",
      "  \u001b[31m   \u001b[0m     _install_setup_requires(attrs)\n",
      "  \u001b[31m   \u001b[0m   File \"/home/saosman/anaconda3/lib/python3.7/site-packages/setuptools/__init__.py\", line 77, in _install_setup_requires\n",
      "  \u001b[31m   \u001b[0m     dist.parse_config_files(ignore_option_errors=True)\n",
      "  \u001b[31m   \u001b[0m   File \"/home/saosman/anaconda3/lib/python3.7/site-packages/setuptools/dist.py\", line 900, in parse_config_files\n",
      "  \u001b[31m   \u001b[0m     self._finalize_requires()\n",
      "  \u001b[31m   \u001b[0m   File \"/home/saosman/anaconda3/lib/python3.7/site-packages/setuptools/dist.py\", line 597, in _finalize_requires\n",
      "  \u001b[31m   \u001b[0m     self._move_install_requirements_markers()\n",
      "  \u001b[31m   \u001b[0m   File \"/home/saosman/anaconda3/lib/python3.7/site-packages/setuptools/dist.py\", line 637, in _move_install_requirements_markers\n",
      "  \u001b[31m   \u001b[0m     inst_reqs = list(_reqs.parse(spec_inst_reqs))\n",
      "  \u001b[31m   \u001b[0m   File \"/home/saosman/anaconda3/lib/python3.7/site-packages/setuptools/_vendor/packaging/requirements.py\", line 37, in __init__\n",
      "  \u001b[31m   \u001b[0m     raise InvalidRequirement(str(e)) from e\n",
      "  \u001b[31m   \u001b[0m setuptools.extern.packaging.requirements.InvalidRequirement: Expected end or semicolon (after name and no valid version specifier)\n",
      "  \u001b[31m   \u001b[0m     python_version>\"3.7\"\n",
      "  \u001b[31m   \u001b[0m                   ^\n",
      "  \u001b[31m   \u001b[0m \u001b[31m[end of output]\u001b[0m\n",
      "  \n",
      "  \u001b[1;35mnote\u001b[0m: This error originates from a subprocess, and is likely not a problem with pip.\n",
      "\u001b[1;31merror\u001b[0m: \u001b[1mmetadata-generation-failed\u001b[0m\n",
      "\n",
      "\u001b[31m×\u001b[0m Encountered error while generating package metadata.\n",
      "\u001b[31m╰─>\u001b[0m See above for output.\n",
      "\n",
      "\u001b[1;35mnote\u001b[0m: This is an issue with the package mentioned above, not pip.\n",
      "\u001b[1;36mhint\u001b[0m: See above for details.\n",
      "\u001b[?25h"
     ]
    }
   ],
   "source": [
    "#!pip install --upgrade pip setuptools wheel\n",
    "# !pip3 install --upgrade pip\n",
    "# !pip install TA_Lib‑0.4.10‑cp35‑cp35m‑win_amd64.whl\n",
    "# !pip install pyproject-toml\n",
    "!pip install ta-lib\n",
    "!pip install pep517\n",
    "!pip install tensorflow tensorflow-gpu opencv-python matplotlib"
   ]
  },
  {
   "cell_type": "code",
   "execution_count": null,
   "metadata": {},
   "outputs": [],
   "source": []
  }
 ],
 "metadata": {
  "kernelspec": {
   "display_name": "Python 3",
   "language": "python",
   "name": "python3"
  },
  "language_info": {
   "codemirror_mode": {
    "name": "ipython",
    "version": 3
   },
   "file_extension": ".py",
   "mimetype": "text/x-python",
   "name": "python",
   "nbconvert_exporter": "python",
   "pygments_lexer": "ipython3",
   "version": "3.7.0"
  }
 },
 "nbformat": 4,
 "nbformat_minor": 2
}
